Workbook
Name TeamPlayers: OFFSET(PlayerListHelper!$A$2, 0, 0, COUNTA(PlayerListHelper!$A:$A)-1, 1)

Sheet Dashboard
A2: Opponent Team | B2: Fairmont
A3: Last 5 Games | B3: TRUE
A7: Opponent Team Profile | E7: Player Profile | H7: Pitching Data
A8: Metric | B8: Value | C8: League AVG | E8: Select Player | F8: K.Thomas | H8: Select Player | I8: D.Haller | J8: Player per Inning | K8: Team Data per Inning | L8: League AVG per Inning
A9: AVG | B9: =IF(B3=TRUE,SUMIFS(Table1[H],Table1[Team],B2,Table1[Last5_Flag],1)/SUMIFS(Table1[AB],Table1[Team],B2,Table1[Last5_Flag],1),SUMIFS(Table1[H],Table1[Team],B2)/SUMIFS(Table1[AB],Table1[Team],B2)) -> 0.33333333 | C9: =IF(B3, SUMIFS(Table1[H], Table1[Last5_Flag], 1) / SUMIFS(Table1[AB], Table1[Last5_Flag], 1), SUM(Table1[H]) / SUM(Table1[AB]) ) -> 0.27603513 | E9: Position | F9: {=IFERROR( _xlfn.TEXTJOIN(", ", TRUE, _xlfn.MAP( _xlfn.TEXTSPLIT(F8, ", "), _xlfn.LAMBDA(_xlpm.player, _xlfn.LET( _xlpm.cleanPlayer, TRIM(_xlpm.player), _xlpm.pos, _xlfn.XLOOKUP(_xlpm.cleanPlayer, Table1[Player Name], Table1[Primary Position], "N/A"), _xlpm.pos ) ) ) ), "N/A")} -> PR | H9: IP | I9: {=IF(B3, IFERROR(INDEX(PitchersKey!B$2:B$100, MATCH(1, (PitchersKey!A$2:A$100=I8)*(PitchersKey!H$2:H$100=1), 0)), 0), IFERROR(INDEX(PitchersKey!B$2:B$100, MATCH(I8, PitchersKey!A$2:A$100, 0)), 0) )} -> 14.667 | J9: {=IF(B3, IFERROR(INDEX(PitchersKey!B$2:B$100, MATCH(1, (PitchersKey!A$2:A$100=I8)*(PitchersKey!H$2:H$100=1), 0)), 0), IFERROR(INDEX(PitchersKey!B$2:B$100, MATCH(I8, PitchersKey!A$2:A$100, 0)), 0) )} -> 14.667 | K9: =IF(B3, SUMIFS(PitchersKey!B$2:B$100, PitchersKey!C$2:C$100, ">0", PitchersKey!H$2:H$100, 1), SUMIFS(PitchersKey!B$2:B$100, PitchersKey!C$2:C$100, ">0") ) -> 33 | L9: =IF(B3, SUMIFS(Table1[IP], Table1[Last5_Flag], 1), SUM(Table1[IP]) ) -> 399.001
A10: OBP | B10: =IF(B3=TRUE,(SUMIFS(Table1[H],Table1[Team],B2,Table1[Last5_Flag],1)+SUMIFS(Table1[BB],Table1[Team],B2,Table1[Last5_Flag],1))/(SUMIFS(Table1[AB],Table1[Team],B2,Table1[Last5_Flag],1)+SUMIFS(Table1[BB],Table1[Team],B2,Table1[Last5_Flag],1)+SUMIFS(Table1[SF],Table1[Team],B2,Table1[Last5_Flag],1)), (SUMIFS(Table1[H],Table1[Team],B2)+SUMIFS(Table1[BB],Table1[Team],B2))/(SUMIFS(Table1[AB],Table1[Team],B2)+SUMIFS(Table1[BB],Table1[Team],B2)+SUMIFS(Table1[SF],Table1[Team],B2))) -> 0.42307692 | C10: =IF(B3, SUMIFS(Table1[Times on Base], Table1[Last5_Flag], 1) / SUMIFS(Table1[OBP Denominator], Table1[Last5_Flag], 1), SUM(Table1[Times on Base]) / SUM(Table1[OBP Denominator]) ) -> 0.34288926 | E10: AB | F10: =IF( Dashboard!$B$3, SUMIFS( Table1[AB], Table1[Player], F8, Table1[Team], Dashboard!$B$2, Table1[Last5_Flag], 1 ), SUMIFS( Table1[AB], Table1[Player], F8, Table1[Team], Dashboard!$B$2 ) ) -> 4 | H10: H_Allowed | I10: {=IF(B3, IFERROR(INDEX(PitchersKey!C$2:C$100, MATCH(1, (PitchersKey!A$2:A$100=I8)*(PitchersKey!H$2:H$100=1), 0)), 0), IFERROR(INDEX(PitchersKey!C$2:C$100, MATCH(I8, PitchersKey!A$2:A$100, 0)), 0) )} -> 13 | J10: =I10/$I$9 -> 0.88634349 | K10: =IF(B3, SUMIFS(PitchersKey!C$2:C$100, PitchersKey!B$2:B$100, ">0", PitchersKey!H$2:H$100, 1) / SUMIFS(PitchersKey!B$2:B$100, PitchersKey!C$2:C$100, ">0", PitchersKey!H$2:H$100, 1), SUMIFS(PitchersKey!C$2:C$100, PitchersKey!B$2:B$100, ">0") / SUMIFS(PitchersKey!B$2:B$100, PitchersKey!C$2:C$100, ">0") ) -> 0.78787879 | L10: =IF(B3, SUMIFS(Table1[H_Allowed], Table1[Position], "*P*", Table1[Last5_Flag], 1) / SUMIFS(Table1[IP], Table1[Position], "*P*", Table1[Last5_Flag], 1), SUMIFS(Table1[H_Allowed], Table1[Position], "*P*") / SUMIFS(Table1[IP], Table1[Position], "*P*") ) -> 1.1027541
A11: SLG | B11: =IF(B3=TRUE, SUMIFS(Table1[TB],Table1[Team],B2,Table1[Last5_Flag],1)/SUMIFS(Table1[AB],Table1[Team],B2,Table1[Last5_Flag],1), SUMIFS(Table1[TB],Table1[Team],B2)/SUMIFS(Table1[AB],Table1[Team],B2)) -> 0.61481481 | C11: =IF(B3, SUMIFS(Table1[TB], Table1[Last5_Flag], 1) / SUMIFS(Table1[AB], Table1[Last5_Flag], 1), SUM(Table1[TB]) / SUM(Table1[AB]) ) -> 0.45420326 | E11: AVG | F11: =IF(B3, SUMIFS(Table1[H], Table1[Team], B2, Table1[Player Name], F8, Table1[Last5_Flag], 1) / SUMIFS(Table1[AB], Table1[Team], B2, Table1[Player Name], F8, Table1[Last5_Flag], 1), SUMIFS(Table1[H], Table1[Team], B2, Table1[Player Name], F8) / SUMIFS(Table1[AB], Table1[Team], B2, Table1[Player Name], F8) ) -> 0 | H11: R_Allowed | I11: {=IF(B3, IFERROR(INDEX(PitchersKey!D$2:D$100, MATCH(1, (PitchersKey!A$2:A$100=I8)*(PitchersKey!H$2:H$100=1), 0)), 0), IFERROR(INDEX(PitchersKey!D$2:D$100, MATCH(I8, PitchersKey!A$2:A$100, 0)), 0) )} -> 3 | J11: =I11/$I$9 -> 0.20454081 | K11: =IF(B3, SUMIFS(PitchersKey!D$2:D$100, PitchersKey!B$2:B$100, ">0", PitchersKey!H$2:H$100, 1) / SUMIFS(PitchersKey!B$2:B$100, PitchersKey!B$2:B$100, ">0", PitchersKey!H$2:H$100, 1), SUMIFS(PitchersKey!D$2:D$100, PitchersKey!B$2:B$100, ">0") / SUMIFS(PitchersKey!B$2:B$100, PitchersKey!B$2:B$100, ">0") ) -> 0.18181818 | L11: =IF(B3, SUMIFS(Table1[R_Allowed], Table1[Position], "*P*", Table1[Last5_Flag], 1) / SUMIFS(Table1[IP], Table1[Position], "*P*", Table1[Last5_Flag], 1), SUMIFS(Table1[R_Allowed], Table1[Position], "*P*") / SUMIFS(Table1[IP], Table1[Position], "*P*") ) -> 0.67669003
A12: Runs/Game | B12: {=IF(B3=TRUE,SUMIFS(Table1[R],Table1[Team],B2,Table1[Last5_Flag],1)/COUNTA(_xlfn.UNIQUE(_xlfn._xlws.FILTER(Table1[Game_ID],(Table1[Team]=B2)*(Table1[Last5_Flag]=1)))),SUMIFS(Table1[R],Table1[Team],B2)/COUNTA(_xlfn.UNIQUE(_xlfn._xlws.FILTER(Table1[Game_ID],Table1[Team]=B2))))} -> 6 | C12: {=IF(B3, SUMIFS(Table1[R], Table1[Last5_Flag], 1) / COUNTA(_xlfn.UNIQUE(_xlfn._xlws.FILTER(Table1[Game_ID], Table1[Last5_Flag]=1))), SUM(Table1[R]) / COUNTA(_xlfn.UNIQUE(Table1[Game_ID])) )} -> 9 | E12: OBP | F12: =IF(B3, (SUMIFS(Table1[H], Table1[Team], B2, Table1[Player Name], F8, Table1[Last5_Flag],1) + SUMIFS(Table1[BB], Table1[Team], B2, Table1[Player Name], F8, Table1[Last5_Flag],1)) / (SUMIFS(Table1[AB], Table1[Team], B2, Table1[Player Name], F8, Table1[Last5_Flag],1) + SUMIFS(Table1[BB], Table1[Team], B2, Table1[Player Name], F8, Table1[Last5_Flag],1) + SUMIFS(Table1[SF], Table1[Team], B2, Table1[Player Name], F8, Table1[Last5_Flag],1)), (SUMIFS(Table1[H], Table1[Team], B2, Table1[Player Name], F8) + SUMIFS(Table1[BB], Table1[Team], B2, Table1[Player Name], F8)) / (SUMIFS(Table1[AB], Table1[Team], B2, Table1[Player Name], F8) + SUMIFS(Table1[BB], Table1[Team], B2, Table1[Player Name], F8) + SUMIFS(Table1[SF], Table1[Team], B2, Table1[Player Name], F8)) ) -> 0 | H12: ER | I12: {=IF(B3, IFERROR(INDEX(PitchersKey!E$2:E$100, MATCH(1, (PitchersKey!A$2:A$100=I8)*(PitchersKey!H$2:H$100=1), 0)), 0), IFERROR(INDEX(PitchersKey!E$2:E$100, MATCH(I8, PitchersKey!A$2:A$100, 0)), 0) )} -> 1 | J12: =I12/$I$9 -> 0.068180269 | K12: =IF(B3, SUMIFS(PitchersKey!E$2:E$100, PitchersKey!B$2:B$100, ">0", PitchersKey!H$2:H$100, 1) / SUMIFS(PitchersKey!B$2:B$100, PitchersKey!B$2:B$100, ">0", PitchersKey!H$2:H$100, 1), SUMIFS(PitchersKey!E$2:E$100, PitchersKey!B$2:B$100, ">0") / SUMIFS(PitchersKey!B$2:B$100, PitchersKey!B$2:B$100, ">0") ) -> 0.12121212 | L12: =IF(B3, SUMIFS(Table1[ER], Table1[Position], "*P*", Table1[Last5_Flag], 1) / SUMIFS(Table1[IP], Table1[Position], "*P*", Table1[Last5_Flag], 1), SUMIFS(Table1[ER], Table1[Position], "*P*") / SUMIFS(Table1[IP], Table1[Position], "*P*") ) -> 0.51628943
A13: SB/Game | B13: {=IF(B3=TRUE,SUMIFS(Table1[SB],Table1[Team],B2,Table1[Last5_Flag],1)/COUNTA(_xlfn.UNIQUE(_xlfn._xlws.FILTER(Table1[Game_ID],(Table1[Team]=B2)*(Table1[Last5_Flag]=1)))),SUMIFS(Table1[SB],Table1[Team],B2)/COUNTA(_xlfn.UNIQUE(_xlfn._xlws.FILTER(Table1[Game_ID],Table1[Team]=B2))))} -> 1.8 | C13: {=IF(B3, SUMIFS(Table1[SB], Table1[Last5_Flag], 1) / COUNTA(_xlfn.UNIQUE(_xlfn._xlws.FILTER(Table1[Game_ID], Table1[Last5_Flag]=1))), SUM(Table1[SB]) / COUNTA(_xlfn.UNIQUE(Table1[Game_ID])) )} -> 2.6666667 | E13: SLG | F13: =IF(B3, SUMIFS(Table1[TB], Table1[Team], B2, Table1[Player Name], F8, Table1[Last5_Flag],1) / SUMIFS(Table1[AB], Table1[Team], B2, Table1[Player Name], F8, Table1[Last5_Flag],1), SUMIFS(Table1[TB], Table1[Team], B2, Table1[Player Name], F8) / SUMIFS(Table1[AB], Table1[Team], B2, Table1[Player Name], F8) ) -> 0 | H13: BB_Allowed | I13: {=IF(B3, IFERROR(INDEX(PitchersKey!F$2:F$100, MATCH(1, (PitchersKey!A$2:A$100=I8)*(PitchersKey!H$2:H$100=1), 0)), 0), IFERROR(INDEX(PitchersKey!F$2:F$100, MATCH(I8, PitchersKey!A$2:A$100, 0)), 0) )} -> 5 | J13: =I13/$I$9 -> 0.34090134 | K13: =IF(B3, SUMIFS(PitchersKey!F$2:F$100, PitchersKey!B$2:B$100, ">0", PitchersKey!H$2:H$100, 1) / SUMIFS(PitchersKey!B$2:B$100, PitchersKey!B$2:B$100, ">0", PitchersKey!H$2:H$100, 1), SUMIFS(PitchersKey!F$2:F$100, PitchersKey!B$2:B$100, ">0") / SUMIFS(PitchersKey!B$2:B$100, PitchersKey!B$2:B$100, ">0") ) -> 0.36363636 | L13: =IF(B3, SUMIFS(Table1[BB_Allowed], Table1[Position], "*P*", Table1[Last5_Flag], 1) / SUMIFS(Table1[IP], Table1[Position], "*P*", Table1[Last5_Flag], 1), SUMIFS(Table1[BB_Allowed], Table1[Position], "*P*") / SUMIFS(Table1[IP], Table1[Position], "*P*") ) -> 0.4260641
A14: Errors/Game | B14: {=IF(B3=TRUE,SUMIFS(Table1[Errors],Table1[Team],B2,Table1[Last5_Flag],1)/COUNTA(_xlfn.UNIQUE(_xlfn._xlws.FILTER(Table1[Game_ID],(Table1[Team]=B2)*(Table1[Last5_Flag]=1)))),SUMIFS(Table1[Errors],Table1[Team],B2)/COUNTA(_xlfn.UNIQUE(_xlfn._xlws.FILTER(Table1[Game_ID],Table1[Team]=B2))))} -> 0.4 | C14: {=IF(B3, SUMIFS(Table1[Errors], Table1[Last5_Flag], 1) / COUNTA(_xlfn.UNIQUE(_xlfn._xlws.FILTER(Table1[Game_ID], Table1[Last5_Flag]=1))), SUM(Table1[Errors]) / COUNTA(_xlfn.UNIQUE(Table1[Game_ID])) )} -> 2.0333333 | E14: K% | F14: =IF(B3, SUMIFS(Table1[SO], Table1[Team], B2, Table1[Player Name], F8, Table1[Last5_Flag],1) / (SUMIFS(Table1[AB], Table1[Team], B2, Table1[Player Name], F8, Table1[Last5_Flag],1) + SUMIFS(Table1[BB], Table1[Team], B2, Table1[Player Name], F8, Table1[Last5_Flag],1) + SUMIFS(Table1[SF], Table1[Team], B2, Table1[Player Name], F8, Table1[Last5_Flag],1)), SUMIFS(Table1[SO], Table1[Team], B2, Table1[Player Name], F8) / (SUMIFS(Table1[AB], Table1[Team], B2, Table1[Player Name], F8) + SUMIFS(Table1[BB], Table1[Team], B2, Table1[Player Name], F8) + SUMIFS(Table1[SF], Table1[Team], B2, Table1[Player Name], F8)) ) -> 0.75 | H14: Strikeouts | I14: {=IF(B3, IFERROR(INDEX(PitchersKey!G$2:G$100, MATCH(1, (PitchersKey!A$2:A$100=I8)*(PitchersKey!H$2:H$100=1), 0)), 0), IFERROR(INDEX(PitchersKey!G$2:G$100, MATCH(I8, PitchersKey!A$2:A$100, 0)), 0) )} -> 10 | J14: =I14/$I$9 -> 0.68180269 | K14: =IF(B3, SUMIFS(PitchersKey!G$2:G$100, PitchersKey!B$2:B$100, ">0", PitchersKey!H$2:H$100, 1) / SUMIFS(PitchersKey!B$2:B$100, PitchersKey!B$2:B$100, ">0", PitchersKey!H$2:H$100, 1), SUMIFS(PitchersKey!G$2:G$100, PitchersKey!B$2:B$100, ">0") / SUMIFS(PitchersKey!B$2:B$100, PitchersKey!B$2:B$100, ">0") ) -> 0.60606061 | L14: =IF(B3, SUMIFS(Table1[K_Pitch], Table1[Position], "*P*", Table1[Last5_Flag], 1) / SUMIFS(Table1[IP], Table1[Position], "*P*", Table1[Last5_Flag], 1), SUMIFS(Table1[K_Pitch], Table1[Position], "*P*") / SUMIFS(Table1[IP], Table1[Position], "*P*") ) -> 0.63157736
A15: K% | B15: =IF(B3, SUMIFS(Table1[SO], Table1[Team], B2, Table1[Last5_Flag], 1) / (SUMIFS(Table1[AB], Table1[Team], B2, Table1[Last5_Flag], 1) + SUMIFS(Table1[BB], Table1[Team], B2, Table1[Last5_Flag], 1)), SUMIFS(Table1[SO], Table1[Team], B2) / (SUMIFS(Table1[AB], Table1[Team], B2) + SUMIFS(Table1[BB], Table1[Team], B2)) ) -> 0.15384615 | C15: =IF(Dashboard!B3, SUMIFS(Table1[SO], Table1[Last5_Flag],1) / (SUMIFS(Table1[AB], Table1[Last5_Flag],1) + SUMIFS(Table1[BB], Table1[Last5_Flag],1)), SUM(Table1[SO]) / (SUM(Table1[AB]) + SUM(Table1[BB])) ) -> 0.14285714 | E15: BB% | F15: =IF(B3, SUMIFS(Table1[BB], Table1[Team], B2, Table1[Player Name], F8, Table1[Last5_Flag],1) / (SUMIFS(Table1[AB], Table1[Team], B2, Table1[Player Name], F8, Table1[Last5_Flag],1) + SUMIFS(Table1[BB], Table1[Team], B2, Table1[Player Name], F8, Table1[Last5_Flag],1) + SUMIFS(Table1[SF], Table1[Team], B2, Table1[Player Name], F8, Table1[Last5_Flag],1)), SUMIFS(Table1[BB], Table1[Team], B2, Table1[Player Name], F8) / (SUMIFS(Table1[AB], Table1[Team], B2, Table1[Player Name], F8) + SUMIFS(Table1[BB], Table1[Team], B2, Table1[Player Name], F8) + SUMIFS(Table1[SF], Table1[Team], B2, Table1[Player Name], F8)) ) -> 0
A16: BB% | B16: =IF(B3, SUMIFS(Table1[BB], Table1[Team], B2, Table1[Last5_Flag], 1) / (SUMIFS(Table1[AB], Table1[Team], B2, Table1[Last5_Flag], 1) + SUMIFS(Table1[BB], Table1[Team], B2, Table1[Last5_Flag], 1)), SUMIFS(Table1[BB], Table1[Team], B2) / (SUMIFS(Table1[AB], Table1[Team], B2) + SUMIFS(Table1[BB], Table1[Team], B2)) ) -> 0.13461538 | C16: =IF(Dashboard!B3, SUMIFS(Table1[BB], Table1[Last5_Flag],1) / (SUMIFS(Table1[AB], Table1[Last5_Flag],1) + SUMIFS(Table1[BB], Table1[Last5_Flag],1)), SUM(Table1[BB]) / (SUM(Table1[AB]) + SUM(Table1[BB])) ) -> 0.096371882 | E16: Fielding Errors | F16: =IF(B3, SUMIFS(Table1[Errors], Table1[Team], B2, Table1[Player Name], F8, Table1[Last5_Flag], 1), SUMIFS(Table1[Errors], Table1[Team], B2, Table1[Player Name], F8) ) -> 0
A18: Lineup Tendencies | H18: Top Hitting Threats by Runs Created
A19: Batting Spot | B19: Most Used Player | C19: Most Frequent Position | D19: AVG | E19: Runs/Game | F19: RBI/Game | H19: Player | I19: AVG | J19: OBP | K19: SLG | L19: OPS | M19: TB | N19: SB | O19: Runs Created
A20: 1 | B20: {=IFERROR( _xlfn.TEXTJOIN(", ", TRUE, _xlfn.UNIQUE( _xlfn._xlws.FILTER( LineupKey!C:C, (LineupKey!A:A=Dashboard!$B$2) * (LineupKey!B:B=Dashboard!A20) * (IF(Dashboard!$B$3, LineupKey!D:D=1, TRUE)) * (LineupKey!E:E=MAX( _xlfn._xlws.FILTER(LineupKey!E:E, (LineupKey!A:A=Dashboard!$B$2) * (LineupKey!B:B=Dashboard!A20) * (IF(Dashboard!$B$3, LineupKey!D:D=1, TRUE)) ) )) ) ) ), "N/A")} -> B.Hess, K.Thomas | C20: {=IFERROR( _xlfn.TEXTJOIN(", ", TRUE, _xlfn.MAP( _xlfn.TEXTSPLIT(B20, ", "), _xlfn.LAMBDA(_xlpm.player, _xlfn.LET( _xlpm.cleanPlayer, TRIM(_xlpm.player), _xlpm.pos, _xlfn.XLOOKUP(_xlpm.cleanPlayer, Table1[Player], Table1[Primary Position], "N/A"), _xlpm.pos ) ) ) ), "N/A")} -> RF, PR | D20: {=_xlfn.LET( _xlpm.players, _xlfn.TEXTSPLIT(B20, ", "), _xlpm.hits, SUM(SUMIFS(Table1[H], Table1[Team], B$2, Table1[Player], _xlpm.players, Table1[Last5_Flag], IF(B$3, 1, "<>"))), _xlpm.ab, SUM(SUMIFS(Table1[AB], Table1[Team], B$2, Table1[Player], _xlpm.players, Table1[Last5_Flag], IF(B$3, 1, "<>"))), IF(_xlpm.ab=0, 0, _xlpm.hits/_xlpm.ab) )} -> 0.42105263 | E20: {=_xlfn.LET( _xlpm.players, _xlfn.TEXTSPLIT(B20, ", "), _xlpm.runs, SUM(SUMIFS(Table1[R], Table1[Team], B$2, Table1[Player], _xlpm.players, Table1[Last5_Flag], IF(B$3, 1, "<>"))), _xlpm.games, COUNTA(_xlfn.UNIQUE(_xlfn._xlws.FILTER(Table1[Game_ID], (Table1[Team]=B$2) * (ISNUMBER(MATCH(Table1[Player Name], _xlpm.players, 0))) * (Table1[Last5_Flag]=IF(B$3, 1, "<>"))))), IF(_xlpm.games=0, 0, _xlpm.runs/_xlpm.games) )} -> 1.4 | F20: {=_xlfn.LET( _xlpm.players, _xlfn.TEXTSPLIT(B20, ", "), _xlpm.rbi, SUM(SUMIFS(Table1[RBI], Table1[Team], B$2, Table1[Player], _xlpm.players, Table1[Last5_Flag], IF(B$3, 1, "<>"))), _xlpm.games, COUNTA(_xlfn.UNIQUE(_xlfn._xlws.FILTER(Table1[Game_ID], (Table1[Team]=B$2) * (ISNUMBER(MATCH(Table1[Player], _xlpm.players, 0))) * (Table1[Last5_Flag]=IF(B$3, 1, "<>"))))), IF(_xlpm.games=0, 0, _xlpm.rbi/_xlpm.games) )} -> 0.8 | H20: {=IF(B3,INDEX(_xlfn.SORTBY(PlayerKey!A2:I100,PlayerKey!I2:I100,-1), _xlfn.SEQUENCE(5), {1,3,4,5,6,7,8,9}), INDEX(_xlfn.SORTBY(PlayerKey!A2:I100,PlayerKey!I2:I100,-1), _xlfn.SEQUENCE(5), {1,3,4,5,6,7,8,9}))} -> B.Marietta | I20: 0.61538462 | J20: 0.66666667 | K20: 1.4615385 | L20: 2.1282051 | M20: 19 | N20: 0 | O20: 10.133333
A21: 2 | B21: {=IFERROR( _xlfn.TEXTJOIN(", ", TRUE, _xlfn.UNIQUE( _xlfn._xlws.FILTER( LineupKey!C:C, (LineupKey!A:A=Dashboard!$B$2) * (LineupKey!B:B=Dashboard!A21) * (IF(Dashboard!$B$3, LineupKey!D:D=1, TRUE)) * (LineupKey!E:E=MAX( _xlfn._xlws.FILTER(LineupKey!E:E, (LineupKey!A:A=Dashboard!$B$2) * (LineupKey!B:B=Dashboard!A21) * (IF(Dashboard!$B$3, LineupKey!D:D=1, TRUE)) ) )) ) ) ), "N/A")} -> A.Townsend, A.Nogay, G.Ramm | C21: {=IFERROR( _xlfn.TEXTJOIN(", ", TRUE, _xlfn.MAP( _xlfn.TEXTSPLIT(B21, ", "), _xlfn.LAMBDA(_xlpm.player, _xlfn.LET( _xlpm.cleanPlayer, TRIM(_xlpm.player), _xlpm.pos, _xlfn.XLOOKUP(_xlpm.cleanPlayer, Table1[Player], Table1[Primary Position], "N/A"), _xlpm.pos ) ) ) ), "N/A")} -> CF, PR, PR | D21: {=_xlfn.LET( _xlpm.players, _xlfn.TEXTSPLIT(B21, ", "), _xlpm.hits, SUM(SUMIFS(Table1[H], Table1[Team], B$2, Table1[Player], _xlpm.players, Table1[Last5_Flag], IF(B$3, 1, "<>"))), _xlpm.ab, SUM(SUMIFS(Table1[AB], Table1[Team], B$2, Table1[Player], _xlpm.players, Table1[Last5_Flag], IF(B$3, 1, "<>"))), IF(_xlpm.ab=0, 0, _xlpm.hits/_xlpm.ab) )} -> 0.3 | E21: {=_xlfn.LET( _xlpm.players, _xlfn.TEXTSPLIT(B21, ", "), _xlpm.runs, SUM(SUMIFS(Table1[R], Table1[Team], B$2, Table1[Player], _xlpm.players, Table1[Last5_Flag], IF(B$3, 1, "<>"))), _xlpm.games, COUNTA(_xlfn.UNIQUE(_xlfn._xlws.FILTER(Table1[Game_ID], (Table1[Team]=B$2) * (ISNUMBER(MATCH(Table1[Player Name], _xlpm.players, 0))) * (Table1[Last5_Flag]=IF(B$3, 1, "<>"))))), IF(_xlpm.games=0, 0, _xlpm.runs/_xlpm.games) )} -> 0.8 | F21: {=_xlfn.LET( _xlpm.players, _xlfn.TEXTSPLIT(B21, ", "), _xlpm.rbi, SUM(SUMIFS(Table1[RBI], Table1[Team], B$2, Table1[Player], _xlpm.players, Table1[Last5_Flag], IF(B$3, 1, "<>"))), _xlpm.games, COUNTA(_xlfn.UNIQUE(_xlfn._xlws.FILTER(Table1[Game_ID], (Table1[Team]=B$2) * (ISNUMBER(MATCH(Table1[Player], _xlpm.players, 0))) * (Table1[Last5_Flag]=IF(B$3, 1, "<>"))))), IF(_xlpm.games=0, 0, _xlpm.rbi/_xlpm.games) )} -> 0.2 | H21: J.McGill | I21: 0.66666667 | J21: 0.75 | K21: 1.1666667 | L21: 1.9166667 | M21: 14 | N21: 1 | O21: 7
A22: 3 | B22: {=IFERROR( _xlfn.TEXTJOIN(", ", TRUE, _xlfn.UNIQUE( _xlfn._xlws.FILTER( LineupKey!C:C, (LineupKey!A:A=Dashboard!$B$2) * (LineupKey!B:B=Dashboard!A22) * (IF(Dashboard!$B$3, LineupKey!D:D=1, TRUE)) * (LineupKey!E:E=MAX( _xlfn._xlws.FILTER(LineupKey!E:E, (LineupKey!A:A=Dashboard!$B$2) * (LineupKey!B:B=Dashboard!A22) * (IF(Dashboard!$B$3, LineupKey!D:D=1, TRUE)) ) )) ) ) ), "N/A")} -> E.Paul, L.Alsop | C22: {=IFERROR( _xlfn.TEXTJOIN(", ", TRUE, _xlfn.MAP( _xlfn.TEXTSPLIT(B22, ", "), _xlfn.LAMBDA(_xlpm.player, _xlfn.LET( _xlpm.cleanPlayer, TRIM(_xlpm.player), _xlpm.pos, _xlfn.XLOOKUP(_xlpm.cleanPlayer, Table1[Player], Table1[Primary Position], "N/A"), _xlpm.pos ) ) ) ), "N/A")} -> SS, P | D22: {=_xlfn.LET( _xlpm.players, _xlfn.TEXTSPLIT(B22, ", "), _xlpm.hits, SUM(SUMIFS(Table1[H], Table1[Team], B$2, Table1[Player], _xlpm.players, Table1[Last5_Flag], IF(B$3, 1, "<>"))), _xlpm.ab, SUM(SUMIFS(Table1[AB], Table1[Team], B$2, Table1[Player], _xlpm.players, Table1[Last5_Flag], IF(B$3, 1, "<>"))), IF(_xlpm.ab=0, 0, _xlpm.hits/_xlpm.ab) )} -> 0.36842105 | E22: {=_xlfn.LET( _xlpm.players, _xlfn.TEXTSPLIT(B22, ", "), _xlpm.runs, SUM(SUMIFS(Table1[R], Table1[Team], B$2, Table1[Player], _xlpm.players, Table1[Last5_Flag], IF(B$3, 1, "<>"))), _xlpm.games, COUNTA(_xlfn.UNIQUE(_xlfn._xlws.FILTER(Table1[Game_ID], (Table1[Team]=B$2) * (ISNUMBER(MATCH(Table1[Player Name], _xlpm.players, 0))) * (Table1[Last5_Flag]=IF(B$3, 1, "<>"))))), IF(_xlpm.games=0, 0, _xlpm.runs/_xlpm.games) )} -> 1.2 | F22: {=_xlfn.LET( _xlpm.players, _xlfn.TEXTSPLIT(B22, ", "), _xlpm.rbi, SUM(SUMIFS(Table1[RBI], Table1[Team], B$2, Table1[Player], _xlpm.players, Table1[Last5_Flag], IF(B$3, 1, "<>"))), _xlpm.games, COUNTA(_xlfn.UNIQUE(_xlfn._xlws.FILTER(Table1[Game_ID], (Table1[Team]=B$2) * (ISNUMBER(MATCH(Table1[Player], _xlpm.players, 0))) * (Table1[Last5_Flag]=IF(B$3, 1, "<>"))))), IF(_xlpm.games=0, 0, _xlpm.rbi/_xlpm.games) )} -> 1.4 | H22: E.Paul | I22: 0.41176471 | J22: 0.47368421 | K22: 0.88235294 | L22: 1.3560372 | M22: 15 | N22: 1 | O22: 5.5263158
A23: 4 | B23: {=IFERROR( _xlfn.TEXTJOIN(", ", TRUE, _xlfn.UNIQUE( _xlfn._xlws.FILTER( LineupKey!C:C, (LineupKey!A:A=Dashboard!$B$2) * (LineupKey!B:B=Dashboard!A23) * (IF(Dashboard!$B$3, LineupKey!D:D=1, TRUE)) * (LineupKey!E:E=MAX( _xlfn._xlws.FILTER(LineupKey!E:E, (LineupKey!A:A=Dashboard!$B$2) * (LineupKey!B:B=Dashboard!A23) * (IF(Dashboard!$B$3, LineupKey!D:D=1, TRUE)) ) )) ) ) ), "N/A")} -> B.Marietta, K.Thomas, A.Nordling | C23: {=IFERROR( _xlfn.TEXTJOIN(", ", TRUE, _xlfn.MAP( _xlfn.TEXTSPLIT(B23, ", "), _xlfn.LAMBDA(_xlpm.player, _xlfn.LET( _xlpm.cleanPlayer, TRIM(_xlpm.player), _xlpm.pos, _xlfn.XLOOKUP(_xlpm.cleanPlayer, Table1[Player], Table1[Primary Position], "N/A"), _xlpm.pos ) ) ) ), "N/A")} -> DP, PR, PH | D23: {=_xlfn.LET( _xlpm.players, _xlfn.TEXTSPLIT(B23, ", "), _xlpm.hits, SUM(SUMIFS(Table1[H], Table1[Team], B$2, Table1[Player], _xlpm.players, Table1[Last5_Flag], IF(B$3, 1, "<>"))), _xlpm.ab, SUM(SUMIFS(Table1[AB], Table1[Team], B$2, Table1[Player], _xlpm.players, Table1[Last5_Flag], IF(B$3, 1, "<>"))), IF(_xlpm.ab=0, 0, _xlpm.hits/_xlpm.ab) )} -> 0.38095238 | E23: {=_xlfn.LET( _xlpm.players, _xlfn.TEXTSPLIT(B23, ", "), _xlpm.runs, SUM(SUMIFS(Table1[R], Table1[Team], B$2, Table1[Player], _xlpm.players, Table1[Last5_Flag], IF(B$3, 1, "<>"))), _xlpm.games, COUNTA(_xlfn.UNIQUE(_xlfn._xlws.FILTER(Table1[Game_ID], (Table1[Team]=B$2) * (ISNUMBER(MATCH(Table1[Player Name], _xlpm.players, 0))) * (Table1[Last5_Flag]=IF(B$3, 1, "<>"))))), IF(_xlpm.games=0, 0, _xlpm.runs/_xlpm.games) )} -> 0.6 | F23: {=_xlfn.LET( _xlpm.players, _xlfn.TEXTSPLIT(B23, ", "), _xlpm.rbi, SUM(SUMIFS(Table1[RBI], Table1[Team], B$2, Table1[Player], _xlpm.players, Table1[Last5_Flag], IF(B$3, 1, "<>"))), _xlpm.games, COUNTA(_xlfn.UNIQUE(_xlfn._xlws.FILTER(Table1[Game_ID], (Table1[Team]=B$2) * (ISNUMBER(MATCH(Table1[Player], _xlpm.players, 0))) * (Table1[Last5_Flag]=IF(B$3, 1, "<>"))))), IF(_xlpm.games=0, 0, _xlpm.rbi/_xlpm.games) )} -> 1.8 | H23: B.Hess | I23: 0.53333333 | J23: 0.61111111 | K23: 0.66666667 | L23: 1.2777778 | M23: 10 | N23: 4 | O23: 4.4444444
A24: 5 | B24: {=IFERROR( _xlfn.TEXTJOIN(", ", TRUE, _xlfn.UNIQUE( _xlfn._xlws.FILTER( LineupKey!C:C, (LineupKey!A:A=Dashboard!$B$2) * (LineupKey!B:B=Dashboard!A24) * (IF(Dashboard!$B$3, LineupKey!D:D=1, TRUE)) * (LineupKey!E:E=MAX( _xlfn._xlws.FILTER(LineupKey!E:E, (LineupKey!A:A=Dashboard!$B$2) * (LineupKey!B:B=Dashboard!A24) * (IF(Dashboard!$B$3, LineupKey!D:D=1, TRUE)) ) )) ) ) ), "N/A")} -> A.Foresha, C.Crowder | C24: {=IFERROR( _xlfn.TEXTJOIN(", ", TRUE, _xlfn.MAP( _xlfn.TEXTSPLIT(B24, ", "), _xlfn.LAMBDA(_xlpm.player, _xlfn.LET( _xlpm.cleanPlayer, TRIM(_xlpm.player), _xlpm.pos, _xlfn.XLOOKUP(_xlpm.cleanPlayer, Table1[Player], Table1[Primary Position], "N/A"), _xlpm.pos ) ) ) ), "N/A")} -> 1B, 1B | D24: {=_xlfn.LET( _xlpm.players, _xlfn.TEXTSPLIT(B24, ", "), _xlpm.hits, SUM(SUMIFS(Table1[H], Table1[Team], B$2, Table1[Player], _xlpm.players, Table1[Last5_Flag], IF(B$3, 1, "<>"))), _xlpm.ab, SUM(SUMIFS(Table1[AB], Table1[Team], B$2, Table1[Player], _xlpm.players, Table1[Last5_Flag], IF(B$3, 1, "<>"))), IF(_xlpm.ab=0, 0, _xlpm.hits/_xlpm.ab) )} -> 0.14285714 | E24: {=_xlfn.LET( _xlpm.players, _xlfn.TEXTSPLIT(B24, ", "), _xlpm.runs, SUM(SUMIFS(Table1[R], Table1[Team], B$2, Table1[Player], _xlpm.players, Table1[Last5_Flag], IF(B$3, 1, "<>"))), _xlpm.games, COUNTA(_xlfn.UNIQUE(_xlfn._xlws.FILTER(Table1[Game_ID], (Table1[Team]=B$2) * (ISNUMBER(MATCH(Table1[Player Name], _xlpm.players, 0))) * (Table1[Last5_Flag]=IF(B$3, 1, "<>"))))), IF(_xlpm.games=0, 0, _xlpm.runs/_xlpm.games) )} -> 0.6 | F24: {=_xlfn.LET( _xlpm.players, _xlfn.TEXTSPLIT(B24, ", "), _xlpm.rbi, SUM(SUMIFS(Table1[RBI], Table1[Team], B$2, Table1[Player], _xlpm.players, Table1[Last5_Flag], IF(B$3, 1, "<>"))), _xlpm.games, COUNTA(_xlfn.UNIQUE(_xlfn._xlws.FILTER(Table1[Game_ID], (Table1[Team]=B$2) * (ISNUMBER(MATCH(Table1[Player], _xlpm.players, 0))) * (Table1[Last5_Flag]=IF(B$3, 1, "<>"))))), IF(_xlpm.games=0, 0, _xlpm.rbi/_xlpm.games) )} -> 0 | H24: A.Townsend | I24: 0.33333333 | J24: 0.375 | K24: 0.33333333 | L24: 0.70833333 | M24: 5 | N24: 0 | O24: 1.5625
A25: 6 | B25: {=IFERROR( _xlfn.TEXTJOIN(", ", TRUE, _xlfn.UNIQUE( _xlfn._xlws.FILTER( LineupKey!C:C, (LineupKey!A:A=Dashboard!$B$2) * (LineupKey!B:B=Dashboard!A25) * (IF(Dashboard!$B$3, LineupKey!D:D=1, TRUE)) * (LineupKey!E:E=MAX( _xlfn._xlws.FILTER(LineupKey!E:E, (LineupKey!A:A=Dashboard!$B$2) * (LineupKey!B:B=Dashboard!A25) * (IF(Dashboard!$B$3, LineupKey!D:D=1, TRUE)) ) )) ) ) ), "N/A")} -> J.McGill, T.Bernard | C25: {=IFERROR( _xlfn.TEXTJOIN(", ", TRUE, _xlfn.MAP( _xlfn.TEXTSPLIT(B25, ", "), _xlfn.LAMBDA(_xlpm.player, _xlfn.LET( _xlpm.cleanPlayer, TRIM(_xlpm.player), _xlpm.pos, _xlfn.XLOOKUP(_xlpm.cleanPlayer, Table1[Player], Table1[Primary Position], "N/A"), _xlpm.pos ) ) ) ), "N/A")} -> 3B, PH | D25: {=_xlfn.LET( _xlpm.players, _xlfn.TEXTSPLIT(B25, ", "), _xlpm.hits, SUM(SUMIFS(Table1[H], Table1[Team], B$2, Table1[Player], _xlpm.players, Table1[Last5_Flag], IF(B$3, 1, "<>"))), _xlpm.ab, SUM(SUMIFS(Table1[AB], Table1[Team], B$2, Table1[Player], _xlpm.players, Table1[Last5_Flag], IF(B$3, 1, "<>"))), IF(_xlpm.ab=0, 0, _xlpm.hits/_xlpm.ab) )} -> 0.61538462 | E25: {=_xlfn.LET( _xlpm.players, _xlfn.TEXTSPLIT(B25, ", "), _xlpm.runs, SUM(SUMIFS(Table1[R], Table1[Team], B$2, Table1[Player], _xlpm.players, Table1[Last5_Flag], IF(B$3, 1, "<>"))), _xlpm.games, COUNTA(_xlfn.UNIQUE(_xlfn._xlws.FILTER(Table1[Game_ID], (Table1[Team]=B$2) * (ISNUMBER(MATCH(Table1[Player Name], _xlpm.players, 0))) * (Table1[Last5_Flag]=IF(B$3, 1, "<>"))))), IF(_xlpm.games=0, 0, _xlpm.runs/_xlpm.games) )} -> 0.6 | F25: {=_xlfn.LET( _xlpm.players, _xlfn.TEXTSPLIT(B25, ", "), _xlpm.rbi, SUM(SUMIFS(Table1[RBI], Table1[Team], B$2, Table1[Player], _xlpm.players, Table1[Last5_Flag], IF(B$3, 1, "<>"))), _xlpm.games, COUNTA(_xlfn.UNIQUE(_xlfn._xlws.FILTER(Table1[Game_ID], (Table1[Team]=B$2) * (ISNUMBER(MATCH(Table1[Player], _xlpm.players, 0))) * (Table1[Last5_Flag]=IF(B$3, 1, "<>"))))), IF(_xlpm.games=0, 0, _xlpm.rbi/_xlpm.games) )} -> 0.6
A26: 7 | B26: {=IFERROR( _xlfn.TEXTJOIN(", ", TRUE, _xlfn.UNIQUE( _xlfn._xlws.FILTER( LineupKey!C:C, (LineupKey!A:A=Dashboard!$B$2) * (LineupKey!B:B=Dashboard!A26) * (IF(Dashboard!$B$3, LineupKey!D:D=1, TRUE)) * (LineupKey!E:E=MAX( _xlfn._xlws.FILTER(LineupKey!E:E, (LineupKey!A:A=Dashboard!$B$2) * (LineupKey!B:B=Dashboard!A26) * (IF(Dashboard!$B$3, LineupKey!D:D=1, TRUE)) ) )) ) ) ), "N/A")} -> P.Matteson, A.Nogay, A.Nordling | C26: {=IFERROR( _xlfn.TEXTJOIN(", ", TRUE, _xlfn.MAP( _xlfn.TEXTSPLIT(B26, ", "), _xlfn.LAMBDA(_xlpm.player, _xlfn.LET( _xlpm.cleanPlayer, TRIM(_xlpm.player), _xlpm.pos, _xlfn.XLOOKUP(_xlpm.cleanPlayer, Table1[Player], Table1[Primary Position], "N/A"), _xlpm.pos ) ) ) ), "N/A")} -> 2B, PR, PH | D26: {=_xlfn.LET( _xlpm.players, _xlfn.TEXTSPLIT(B26, ", "), _xlpm.hits, SUM(SUMIFS(Table1[H], Table1[Team], B$2, Table1[Player], _xlpm.players, Table1[Last5_Flag], IF(B$3, 1, "<>"))), _xlpm.ab, SUM(SUMIFS(Table1[AB], Table1[Team], B$2, Table1[Player], _xlpm.players, Table1[Last5_Flag], IF(B$3, 1, "<>"))), IF(_xlpm.ab=0, 0, _xlpm.hits/_xlpm.ab) )} -> 0.15789474 | E26: {=_xlfn.LET( _xlpm.players, _xlfn.TEXTSPLIT(B26, ", "), _xlpm.runs, SUM(SUMIFS(Table1[R], Table1[Team], B$2, Table1[Player], _xlpm.players, Table1[Last5_Flag], IF(B$3, 1, "<>"))), _xlpm.games, COUNTA(_xlfn.UNIQUE(_xlfn._xlws.FILTER(Table1[Game_ID], (Table1[Team]=B$2) * (ISNUMBER(MATCH(Table1[Player Name], _xlpm.players, 0))) * (Table1[Last5_Flag]=IF(B$3, 1, "<>"))))), IF(_xlpm.games=0, 0, _xlpm.runs/_xlpm.games) )} -> 0.6 | F26: {=_xlfn.LET( _xlpm.players, _xlfn.TEXTSPLIT(B26, ", "), _xlpm.rbi, SUM(SUMIFS(Table1[RBI], Table1[Team], B$2, Table1[Player], _xlpm.players, Table1[Last5_Flag], IF(B$3, 1, "<>"))), _xlpm.games, COUNTA(_xlfn.UNIQUE(_xlfn._xlws.FILTER(Table1[Game_ID], (Table1[Team]=B$2) * (ISNUMBER(MATCH(Table1[Player], _xlpm.players, 0))) * (Table1[Last5_Flag]=IF(B$3, 1, "<>"))))), IF(_xlpm.games=0, 0, _xlpm.rbi/_xlpm.games) )} -> 0.6
A27: 8 | B27: {=IFERROR( _xlfn.TEXTJOIN(", ", TRUE, _xlfn.UNIQUE( _xlfn._xlws.FILTER( LineupKey!C:C, (LineupKey!A:A=Dashboard!$B$2) * (LineupKey!B:B=Dashboard!A27) * (IF(Dashboard!$B$3, LineupKey!D:D=1, TRUE)) * (LineupKey!E:E=MAX( _xlfn._xlws.FILTER(LineupKey!E:E, (LineupKey!A:A=Dashboard!$B$2) * (LineupKey!B:B=Dashboard!A27) * (IF(Dashboard!$B$3, LineupKey!D:D=1, TRUE)) ) )) ) ) ), "N/A")} -> G.Bibb, A.Nordling, L.Alsop, S.Emanuel, A.Nogay | C27: {=IFERROR( _xlfn.TEXTJOIN(", ", TRUE, _xlfn.MAP( _xlfn.TEXTSPLIT(B27, ", "), _xlfn.LAMBDA(_xlpm.player, _xlfn.LET( _xlpm.cleanPlayer, TRIM(_xlpm.player), _xlpm.pos, _xlfn.XLOOKUP(_xlpm.cleanPlayer, Table1[Player], Table1[Primary Position], "N/A"), _xlpm.pos ) ) ) ), "N/A")} -> LF, PH, P, LF, PR | D27: {=_xlfn.LET( _xlpm.players, _xlfn.TEXTSPLIT(B27, ", "), _xlpm.hits, SUM(SUMIFS(Table1[H], Table1[Team], B$2, Table1[Player], _xlpm.players, Table1[Last5_Flag], IF(B$3, 1, "<>"))), _xlpm.ab, SUM(SUMIFS(Table1[AB], Table1[Team], B$2, Table1[Player], _xlpm.players, Table1[Last5_Flag], IF(B$3, 1, "<>"))), IF(_xlpm.ab=0, 0, _xlpm.hits/_xlpm.ab) )} -> 0.11111111 | E27: {=_xlfn.LET( _xlpm.players, _xlfn.TEXTSPLIT(B27, ", "), _xlpm.runs, SUM(SUMIFS(Table1[R], Table1[Team], B$2, Table1[Player], _xlpm.players, Table1[Last5_Flag], IF(B$3, 1, "<>"))), _xlpm.games, COUNTA(_xlfn.UNIQUE(_xlfn._xlws.FILTER(Table1[Game_ID], (Table1[Team]=B$2) * (ISNUMBER(MATCH(Table1[Player Name], _xlpm.players, 0))) * (Table1[Last5_Flag]=IF(B$3, 1, "<>"))))), IF(_xlpm.games=0, 0, _xlpm.runs/_xlpm.games) )} -> 0.4 | F27: {=_xlfn.LET( _xlpm.players, _xlfn.TEXTSPLIT(B27, ", "), _xlpm.rbi, SUM(SUMIFS(Table1[RBI], Table1[Team], B$2, Table1[Player], _xlpm.players, Table1[Last5_Flag], IF(B$3, 1, "<>"))), _xlpm.games, COUNTA(_xlfn.UNIQUE(_xlfn._xlws.FILTER(Table1[Game_ID], (Table1[Team]=B$2) * (ISNUMBER(MATCH(Table1[Player], _xlpm.players, 0))) * (Table1[Last5_Flag]=IF(B$3, 1, "<>"))))), IF(_xlpm.games=0, 0, _xlpm.rbi/_xlpm.games) )} -> 0.4
A28: 9 | B28: {=IFERROR( _xlfn.TEXTJOIN(", ", TRUE, _xlfn.UNIQUE( _xlfn._xlws.FILTER( LineupKey!C:C, (LineupKey!A:A=Dashboard!$B$2) * (LineupKey!B:B=Dashboard!A28) * (IF(Dashboard!$B$3, LineupKey!D:D=1, TRUE)) * (LineupKey!E:E=MAX( _xlfn._xlws.FILTER(LineupKey!E:E, (LineupKey!A:A=Dashboard!$B$2) * (LineupKey!B:B=Dashboard!A28) * (IF(Dashboard!$B$3, LineupKey!D:D=1, TRUE)) ) )) ) ) ), "N/A")} -> A.Keilholz, C.Boggs | C28: {=IFERROR( _xlfn.TEXTJOIN(", ", TRUE, _xlfn.MAP( _xlfn.TEXTSPLIT(B28, ", "), _xlfn.LAMBDA(_xlpm.player, _xlfn.LET( _xlpm.cleanPlayer, TRIM(_xlpm.player), _xlpm.pos, _xlfn.XLOOKUP(_xlpm.cleanPlayer, Table1[Player], Table1[Primary Position], "N/A"), _xlpm.pos ) ) ) ), "N/A")} -> C, PH | D28: {=_xlfn.LET( _xlpm.players, _xlfn.TEXTSPLIT(B28, ", "), _xlpm.hits, SUM(SUMIFS(Table1[H], Table1[Team], B$2, Table1[Player], _xlpm.players, Table1[Last5_Flag], IF(B$3, 1, "<>"))), _xlpm.ab, SUM(SUMIFS(Table1[AB], Table1[Team], B$2, Table1[Player], _xlpm.players, Table1[Last5_Flag], IF(B$3, 1, "<>"))), IF(_xlpm.ab=0, 0, _xlpm.hits/_xlpm.ab) )} -> 0.21428571 | E28: {=_xlfn.LET( _xlpm.players, _xlfn.TEXTSPLIT(B28, ", "), _xlpm.runs, SUM(SUMIFS(Table1[R], Table1[Team], B$2, Table1[Player], _xlpm.players, Table1[Last5_Flag], IF(B$3, 1, "<>"))), _xlpm.games, COUNTA(_xlfn.UNIQUE(_xlfn._xlws.FILTER(Table1[Game_ID], (Table1[Team]=B$2) * (ISNUMBER(MATCH(Table1[Player Name], _xlpm.players, 0))) * (Table1[Last5_Flag]=IF(B$3, 1, "<>"))))), IF(_xlpm.games=0, 0, _xlpm.runs/_xlpm.games) )} -> 0.4 | F28: {=_xlfn.LET( _xlpm.players, _xlfn.TEXTSPLIT(B28, ", "), _xlpm.rbi, SUM(SUMIFS(Table1[RBI], Table1[Team], B$2, Table1[Player], _xlpm.players, Table1[Last5_Flag], IF(B$3, 1, "<>"))), _xlpm.games, COUNTA(_xlfn.UNIQUE(_xlfn._xlws.FILTER(Table1[Game_ID], (Table1[Team]=B$2) * (ISNUMBER(MATCH(Table1[Player], _xlpm.players, 0))) * (Table1[Last5_Flag]=IF(B$3, 1, "<>"))))), IF(_xlpm.games=0, 0, _xlpm.rbi/_xlpm.games) )} -> 0.6
A29: Pitcher | B29: {=_xlfn.LET( _xlpm.players, _xlfn.UNIQUE(_xlfn._xlws.FILTER(Table1[Player Name], (Table1[Team]=Dashboard!$B$2) * (Table1[Position]="P") )), _xlpm.ipTotals, _xlfn.MAP(_xlpm.players, _xlfn.LAMBDA(_xlpm.p, IF(Dashboard!$B$3, SUMIFS(Table1[IP], Table1[Player Name], _xlpm.p, Table1[Team], Dashboard!$B$2, Table1[Position], "P", Table1[Last5_Flag], 1 ), SUMIFS(Table1[IP], Table1[Player Name], _xlpm.p, Table1[Team], Dashboard!$B$2, Table1[Position], "P" ) ) ) ), INDEX(_xlpm.players, MATCH(MAX(_xlpm.ipTotals), _xlpm.ipTotals, 0)) )} -> D.Haller | C29: {=IFERROR( _xlfn.TEXTJOIN(", ", TRUE, _xlfn.MAP( _xlfn.TEXTSPLIT(B29, ", "), _xlfn.LAMBDA(_xlpm.player, _xlfn.LET( _xlpm.cleanPlayer, TRIM(_xlpm.player), _xlpm.pos, _xlfn.XLOOKUP(_xlpm.cleanPlayer, Table1[Player], Table1[Primary Position], "N/A"), _xlpm.pos ) ) ) ), "N/A")} -> P
A31: Summary Scouting Report
A32: Offensive Strength | D32: Base Running Threat
A33: =IF(B9 > C9*1.05, "🔥 Strong offense team (Above League AVG)", "➖ Average offense (Below League AVG)" ) -> 🔥 Strong offense team (Above League AVG) | D33: =IF(B13 > C13*1.1,"Aggressive baserunning","Limited steal threat") -> Limited steal threat
A34: Offensive Style | D34: Defensive Reliability
A35: =IF(B11 > C11*1.1,"Power-heavy offense", IF(B11 > C11*1.05,"Contact-heavy lineup", "Balanced offense")) -> Power-heavy offense | D35: =IF(B14 < C14 *1.1,"Defensively solid team","Error prone defense") -> Defensively solid team
A36: Top vs Bottom Lineup | D36: Pitching Strength
A37: =_xlfn.LET( _xlpm.topRuns, SUMIFS(E20:E28, A20:A28, "<=5"), _xlpm.bottomRuns, SUMIFS(E20:E28, A20:A28, ">=6"), _xlpm.topRBI, SUMIFS(F20:F28, A20:A28, "<=5"), _xlpm.bottomRBI, SUMIFS(F20:F28, A20:A28, ">=6"), IF(AND(_xlpm.topRuns > _xlpm.bottomRuns*1.2, _xlpm.bottomRBI > _xlpm.topRBI*1.2), "🔥 Strong table setters + clutch depth", IF( _xlpm.topRuns > _xlpm.bottomRuns*1.2, "⚠️ Top heavy lineup (production concentrated in 1-5)", IF(_xlpm.bottomRBI > _xlpm.topRBI*1.2, "⚠️ Depth-driven lineup (bottom producing RBIs)", "➖ Balanced lineup production" ) ) )) -> ⚠️ Top heavy lineup (production concentrated in 1-5) | D37: =IF(K12 > L12*1.1, "⚠️ Vulnerable pitching staff", IF(K13 > L13*1.1, "Control issues (high walks)", "➖ Average pitching")) -> ➖ Average pitching
A38: Plate Discipline | D38: Pitching Style
A39: =IF(B15 > C15*1.1, "⚠️ High strikeout lineup | K%: " & TEXT(B15,"0.0%") & " (League " & TEXT(C15,"0.0%") & ") | BB%: " & TEXT(B16,"0.0%") & " (League " & TEXT(C16,"0.0%") & ")", IF(B16 > C16*1.1, "Disciplined hitters (draw walks) | K%: " & TEXT(B15,"0.0%") & " (League " & TEXT(C15,"0.0%") & ") | BB%: " & TEXT(B16,"0.0%") & " (League " & TEXT(C16,"0.0%") & ")", "➖ Average plate discipline | K%: " & TEXT(B15,"0.0%") & " (League " & TEXT(C15,"0.0%") & ") | BB%: " & TEXT(B16,"0.0%") & " (League " & TEXT(C16,"0.0%") & ")" ) ) -> Disciplined hitters (draw walks) | K%: 15.4% (League 14.3%) | BB%: 13.5% (League 9.6%) | D39: =IF(K14 > L14*1.1, "Strikeout heavy staff", IF(K14< L14*0.9, "Contact pitching staff", "Balanced pitching staff")) -> Balanced pitching staff
A40: Team Hitting Momentum (Based on Runs/Game) | D40: Selected Pitcher Momentum (by ER)
A41: {=IF( B3, IF( SUMIFS(Table1[R], Table1[Team], $B$2, Table1[Last5_Flag], 1) / COUNTA(_xlfn.UNIQUE(_xlfn._xlws.FILTER(Table1[Team_Game_Number], (Table1[Team]=$B$2)*(Table1[Last5_Flag]=1)))) > C12, "🔥 Team offense hot recently", "⚠️ Team struggling in last 5 games" ), "Toggle B3 for last 5 games" )} -> ⚠️ Team struggling in last 5 games | D41: =IF(B3, IF(J12 < L12, "🔥 Hot pitcher recently", "⚠️ Struggling in last 5 games"), "Toggle B3 for last 5 games" ) -> 🔥 Hot pitcher recently

Sheet BoxScores_Master
A1: Game_ID | B1: Date | C1: Game_no. | D1: Home Team | E1: Away Team | F1: Team | G1: Opponent | H1: Player | I1: Player Name | J1: AB | K1: R | L1: H | M1: RBI | N1: BB | O1: SO | P1: 2B | Q1: 3B | R1: HR | S1: SB | T1: CS | U1: SF | V1: TB | W1: Position | X1: Batting_Spot | Y1: Errors | Z1: IP | AA1: H_Allowed | AB1: R_Allowed | AC1: ER | AD1: BB_Allowed | AE1: K_Pitch | AF1: OBP Denominator | AG1: Times on Base | AH1: Singles | AI1: Last5_Flag | AJ1: Team_Game_Number | AK1: Spot_Last5_Flag | AL1: Primary Position Count | AM1: Primary Position
A2: =TEXT(Table1[[#This Row],[Date]],"yyyymmdd") & "_" & (LEFT(D2,3) & "_" & LEFT(E2,3) & "_" & (Table1[[#This Row],[Game_no.]])) -> 20260130_UNC_D&E_1 | B2: 46052 | C2: 1 | D2: UNC Pembroke | E2: D&E | F2: D&E | G2: UNC Pembroke | H2: C.Dobbs | I2: =TRIM(SUBSTITUTE(Table1[[#This Row],[Player]], " ", "")) -> C.Dobbs | J2: 2 | K2: 0 | L2: 0 | M2: 1 | N2: 1 | O2: 1 | P2: 0 | Q2: 0 | R2: 0 | S2: 0 | T2: 0 | U2: 0 | V2: =L2*1+P2*2+Q2*3+R2*4 -> 0 | W2: 2B | X2: 1 | Y2: 0 | AF2: =Table1[[#This Row],[AB]]+Table1[[#This Row],[BB]]+Table1[[#This Row],[SF]] -> 3 | AG2: =Table1[[#This Row],[H]]+Table1[[#This Row],[BB]] -> 1 | AH2: =Table1[[#This Row],[H]]-Table1[[#This Row],[2B]]-Table1[[#This Row],[3B]]-Table1[[#This Row],[HR]] -> 0 | AI2: =IF(Table1[[#This Row],[Team_Game_Number]] >_xlfn.MAXIFS(Table1[Team_Game_Number],Table1[Team],Table1[[#This Row],[Team]]) - 5,1,0) -> 0 | AJ2: {=MATCH(Table1[[#This Row],[Game_ID]],_xlfn.UNIQUE(_xlfn._xlws.FILTER(Table1[Game_ID],Table1[Team]=Table1[[#This Row],[Team]])),0)} -> 1 | AK2: =IF(Table1[[#This Row],[Last5_Flag]]=1,1,0) -> 0 | AL2: =COUNTIFS( Table1[Player Name], Table1[[#This Row],[Player Name]], Table1[Position], Table1[[#This Row],[Position]] ) -> 3 | AM2: {=IFERROR( _xlfn.LET( _xlpm.player, Table1[[#This Row],[Player Name]], _xlpm.uPos, _xlfn.UNIQUE(_xlfn._xlws.FILTER(Table1[Position], Table1[Player Name]=_xlpm.player)), _xlpm.counts, _xlfn.MAP(_xlpm.uPos, _xlfn.LAMBDA(_xlpm.p, COUNTIFS(Table1[Player Name], _xlpm.player, Table1[Position], _xlpm.p))), INDEX(_xlpm.uPos, MATCH(MAX(_xlpm.counts), _xlpm.counts, 0)) ), "N/A")} -> SS
A3: =TEXT(Table1[[#This Row],[Date]],"yyyymmdd") & "_" & (LEFT(D3,3) & "_" & LEFT(E3,3) & "_" & (Table1[[#This Row],[Game_no.]])) -> 20260130_UNC_D&E_1 | B3: 46052 | C3: 1 | D3: UNC Pembroke | E3: D&E | F3: D&E | G3: UNC Pembroke | H3: M.Henkle | I3: =TRIM(SUBSTITUTE(Table1[[#This Row],[Player]], " ", "")) -> M.Henkle | J3: 3 | K3: 0 | L3: 0 | M3: 0 | N3: 0 | O3: 2 | P3: 0 | Q3: 0 | R3: 0 | S3: 0 | T3: 0 | U3: 0 | V3: =L3*1+P3*2+Q3*3+R3*4 -> 0 | W3: 3B | X3: 2 | Y3: 0 | AF3: =Table1[[#This Row],[AB]]+Table1[[#This Row],[BB]]+Table1[[#This Row],[SF]] -> 3 | AG3: =Table1[[#This Row],[H]]+Table1[[#This Row],[BB]] -> 0 | AH3: =Table1[[#This Row],[H]]-Table1[[#This Row],[2B]]-Table1[[#This Row],[3B]]-Table1[[#This Row],[HR]] -> 0 | AI3: =IF(Table1[[#This Row],[Team_Game_Number]] >_xlfn.MAXIFS(Table1[Team_Game_Number],Table1[Team],Table1[[#This Row],[Team]]) - 5,1,0) -> 0 | AJ3: {=MATCH(Table1[[#This Row],[Game_ID]],_xlfn.UNIQUE(_xlfn._xlws.FILTER(Table1[Game_ID],Table1[Team]=Table1[[#This Row],[Team]])),0)} -> 1 | AK3: =IF(Table1[[#This Row],[Last5_Flag]]=1,1,0) -> 0 | AL3: =COUNTIFS( Table1[Player Name], Table1[[#This Row],[Player Name]], Table1[Position], Table1[[#This Row],[Position]] ) -> 13 | AM3: {=IFERROR( _xlfn.LET( _xlpm.player, Table1[[#This Row],[Player Name]], _xlpm.uPos, _xlfn.UNIQUE(_xlfn._xlws.FILTER(Table1[Position], Table1[Player Name]=_xlpm.player)), _xlpm.counts, _xlfn.MAP(_xlpm.uPos, _xlfn.LAMBDA(_xlpm.p, COUNTIFS(Table1[Player Name], _xlpm.player, Table1[Position], _xlpm.p))), INDEX(_xlpm.uPos, MATCH(MAX(_xlpm.counts), _xlpm.counts, 0)) ), "N/A")} -> 3B
A4: =TEXT(Table1[[#This Row],[Date]],"yyyymmdd") & "_" & (LEFT(D4,3) & "_" & LEFT(E4,3) & "_" & (Table1[[#This Row],[Game_no.]])) -> 20260130_UNC_D&E_1 | B4: 46052 | C4: 1 | D4: UNC Pembroke | E4: D&E | F4: D&E | G4: UNC Pembroke | H4: A.Zapach | I4: =TRIM(SUBSTITUTE(Table1[[#This Row],[Player]], " ", "")) -> A.Zapach | J4: 2 | K4: 1 | L4: 1 | M4: 0 | N4: 1 | O4: 0 | P4: 0 | Q4: 0 | R4: 0 | S4: 0 | T4: 0 | U4: 0 | V4: =L4*1+P4*2+Q4*3+R4*4 -> 1 | W4: 1B | X4: 3 | Y4: 0 | AF4: =Table1[[#This Row],[AB]]+Table1[[#This Row],[BB]]+Table1[[#This Row],[SF]] -> 3 | AG4: =Table1[[#This Row],[H]]+Table1[[#This Row],[BB]] -> 2 | AH4: =Table1[[#This Row],[H]]-Table1[[#This Row],[2B]]-Table1[[#This Row],[3B]]-Table1[[#This Row],[HR]] -> 1 | AI4: =IF(Table1[[#This Row],[Team_Game_Number]] >_xlfn.MAXIFS(Table1[Team_Game_Number],Table1[Team],Table1[[#This Row],[Team]]) - 5,1,0) -> 0 | AJ4: {=MATCH(Table1[[#This Row],[Game_ID]],_xlfn.UNIQUE(_xlfn._xlws.FILTER(Table1[Game_ID],Table1[Team]=Table1[[#This Row],[Team]])),0)} -> 1 | AK4: =IF(Table1[[#This Row],[Last5_Flag]]=1,1,0) -> 0 | AL4: =COUNTIFS( Table1[Player Name], Table1[[#This Row],[Player Name]], Table1[Position], Table1[[#This Row],[Position]] ) -> 27 | AM4: {=IFERROR( _xlfn.LET( _xlpm.player, Table1[[#This Row],[Player Name]], _xlpm.uPos, _xlfn.UNIQUE(_xlfn._xlws.FILTER(Table1[Position], Table1[Player Name]=_xlpm.player)), _xlpm.counts, _xlfn.MAP(_xlpm.uPos, _xlfn.LAMBDA(_xlpm.p, COUNTIFS(Table1[Player Name], _xlpm.player, Table1[Position], _xlpm.p))), INDEX(_xlpm.uPos, MATCH(MAX(_xlpm.counts), _xlpm.counts, 0)) ), "N/A")} -> 1B
A5: =TEXT(Table1[[#This Row],[Date]],"yyyymmdd") & "_" & (LEFT(D5,3) & "_" & LEFT(E5,3) & "_" & (Table1[[#This Row],[Game_no.]])) -> 20260130_UNC_D&E_1 | B5: 46052 | C5: 1 | D5: UNC Pembroke | E5: D&E | F5: D&E | G5: UNC Pembroke | H5: A.Higgins | I5: =TRIM(SUBSTITUTE(Table1[[#This Row],[Player]], " ", "")) -> A.Higgins | J5: 2 | K5: 1 | L5: 1 | M5: 0 | N5: 1 | O5: 1 | P5: 0 | Q5: 0 | R5: 0 | S5: 0 | T5: 0 | U5: 0 | V5: =L5*1+P5*2+Q5*3+R5*4 -> 1 | W5: SS | X5: 4 | Y5: 1 | AF5: =Table1[[#This Row],[AB]]+Table1[[#This Row],[BB]]+Table1[[#This Row],[SF]] -> 3 | AG5: =Table1[[#This Row],[H]]+Table1[[#This Row],[BB]] -> 2 | AH5: =Table1[[#This Row],[H]]-Table1[[#This Row],[2B]]-Table1[[#This Row],[3B]]-Table1[[#This Row],[HR]] -> 1 | AI5: =IF(Table1[[#This Row],[Team_Game_Number]] >_xlfn.MAXIFS(Table1[Team_Game_Number],Table1[Team],Table1[[#This Row],[Team]]) - 5,1,0) -> 0 | AJ5: {=MATCH(Table1[[#This Row],[Game_ID]],_xlfn.UNIQUE(_xlfn._xlws.FILTER(Table1[Game_ID],Table1[Team]=Table1[[#This Row],[Team]])),0)} -> 1 | AK5: =IF(Table1[[#This Row],[Last5_Flag]]=1,1,0) -> 0 | AL5: =COUNTIFS( Table1[Player Name], Table1[[#This Row],[Player Name]], Table1[Position], Table1[[#This Row],[Position]] ) -> 22 | AM5: {=IFERROR( _xlfn.LET( _xlpm.player, Table1[[#This Row],[Player Name]], _xlpm.uPos, _xlfn.UNIQUE(_xlfn._xlws.FILTER(Table1[Position], Table1[Player Name]=_xlpm.player)), _xlpm.counts, _xlfn.MAP(_xlpm.uPos, _xlfn.LAMBDA(_xlpm.p, COUNTIFS(Table1[Player Name], _xlpm.player, Table1[Position], _xlpm.p))), INDEX(_xlpm.uPos, MATCH(MAX(_xlpm.counts), _xlpm.counts, 0)) ), "N/A")} -> SS
A6: =TEXT(Table1[[#This Row],[Date]],"yyyymmdd") & "_" & (LEFT(D6,3) & "_" & LEFT(E6,3) & "_" & (Table1[[#This Row],[Game_no.]])) -> 20260130_UNC_D&E_1 | B6: 46052 | C6: 1 | D6: UNC Pembroke | E6: D&E | F6: D&E | G6: UNC Pembroke | H6: T.Fleming | I6: =TRIM(SUBSTITUTE(Table1[[#This Row],[Player]], " ", "")) -> T.Fleming | J6: 3 | K6: 1 | L6: 1 | M6: 0 | N6: 0 | O6: 0 | P6: 0 | Q6: 0 | R6: 0 | S6: 0 | T6: 0 | U6: 0 | V6: =L6*1+P6*2+Q6*3+R6*4 -> 1 | W6: DP | X6: 5 | Y6: 0 | AF6: =Table1[[#This Row],[AB]]+Table1[[#This Row],[BB]]+Table1[[#This Row],[SF]] -> 3 | AG6: =Table1[[#This Row],[H]]+Table1[[#This Row],[BB]] -> 1 | AH6: =Table1[[#This Row],[H]]-Table1[[#This Row],[2B]]-Table1[[#This Row],[3B]]-Table1[[#This Row],[HR]] -> 1 | AI6: =IF(Table1[[#This Row],[Team_Game_Number]] >_xlfn.MAXIFS(Table1[Team_Game_Number],Table1[Team],Table1[[#This Row],[Team]]) - 5,1,0) -> 0 | AJ6: {=MATCH(Table1[[#This Row],[Game_ID]],_xlfn.UNIQUE(_xlfn._xlws.FILTER(Table1[Game_ID],Table1[Team]=Table1[[#This Row],[Team]])),0)} -> 1 | AK6: =IF(Table1[[#This Row],[Last5_Flag]]=1,1,0) -> 0 | AL6: =COUNTIFS( Table1[Player Name], Table1[[#This Row],[Player Name]], Table1[Position], Table1[[#This Row],[Position]] ) -> 11 | AM6: {=IFERROR( _xlfn.LET( _xlpm.player, Table1[[#This Row],[Player Name]], _xlpm.uPos, _xlfn.UNIQUE(_xlfn._xlws.FILTER(Table1[Position], Table1[Player Name]=_xlpm.player)), _xlpm.counts, _xlfn.MAP(_xlpm.uPos, _xlfn.LAMBDA(_xlpm.p, COUNTIFS(Table1[Player Name], _xlpm.player, Table1[Position], _xlpm.p))), INDEX(_xlpm.uPos, MATCH(MAX(_xlpm.counts), _xlpm.counts, 0)) ), "N/A")} -> 2B
A7: =TEXT(Table1[[#This Row],[Date]],"yyyymmdd") & "_" & (LEFT(D7,3) & "_" & LEFT(E7,3) & "_" & (Table1[[#This Row],[Game_no.]])) -> 20260130_UNC_D&E_1 | B7: 46052 | C7: 1 | D7: UNC Pembroke | E7: D&E | F7: D&E | G7: UNC Pembroke | H7: G.Wessling | I7: =TRIM(SUBSTITUTE(Table1[[#This Row],[Player]], " ", "")) -> G.Wessling | J7: 3 | K7: 1 | L7: 1 | M7: 1 | N7: 0 | O7: 1 | P7: 0 | Q7: 0 | R7: 0 | S7: 0 | T7: 0 | U7: 0 | V7: =L7*1+P7*2+Q7*3+R7*4 -> 1 | W7: C | X7: 6 | Y7: 0 | AF7: =Table1[[#This Row],[AB]]+Table1[[#This Row],[BB]]+Table1[[#This Row],[SF]] -> 3 | AG7: =Table1[[#This Row],[H]]+Table1[[#This Row],[BB]] -> 1 | AH7: =Table1[[#This Row],[H]]-Table1[[#This Row],[2B]]-Table1[[#This Row],[3B]]-Table1[[#This Row],[HR]] -> 1 | AI7: =IF(Table1[[#This Row],[Team_Game_Number]] >_xlfn.MAXIFS(Table1[Team_Game_Number],Table1[Team],Table1[[#This Row],[Team]]) - 5,1,0) -> 0 | AJ7: {=MATCH(Table1[[#This Row],[Game_ID]],_xlfn.UNIQUE(_xlfn._xlws.FILTER(Table1[Game_ID],Table1[Team]=Table1[[#This Row],[Team]])),0)} -> 1 | AK7: =IF(Table1[[#This Row],[Last5_Flag]]=1,1,0) -> 0 | AL7: =COUNTIFS( Table1[Player Name], Table1[[#This Row],[Player Name]], Table1[Position], Table1[[#This Row],[Position]] ) -> 26 | AM7: {=IFERROR( _xlfn.LET( _xlpm.player, Table1[[#This Row],[Player Name]], _xlpm.uPos, _xlfn.UNIQUE(_xlfn._xlws.FILTER(Table1[Position], Table1[Player Name]=_xlpm.player)), _xlpm.counts, _xlfn.MAP(_xlpm.uPos, _xlfn.LAMBDA(_xlpm.p, COUNTIFS(Table1[Player Name], _xlpm.player, Table1[Position], _xlpm.p))), INDEX(_xlpm.uPos, MATCH(MAX(_xlpm.counts), _xlpm.counts, 0)) ), "N/A")} -> C
A8: =TEXT(Table1[[#This Row],[Date]],"yyyymmdd") & "_" & (LEFT(D8,3) & "_" & LEFT(E8,3) & "_" & (Table1[[#This Row],[Game_no.]])) -> 20260130_UNC_D&E_1 | B8: 46052 | C8: 1 | D8: UNC Pembroke | E8: D&E | F8: D&E | G8: UNC Pembroke | H8: C.Montgomery | I8: =TRIM(SUBSTITUTE(Table1[[#This Row],[Player]], " ", "")) -> C.Montgomery | J8: 3 | K8: 0 | L8: 1 | M8: 0 | N8: 0 | O8: 1 | P8: 0 | Q8: 0 | R8: 0 | S8: 0 | T8: 0 | U8: 0 | V8: =L8*1+P8*2+Q8*3+R8*4 -> 1 | W8: LF | X8: 7 | Y8: 0 | AF8: =Table1[[#This Row],[AB]]+Table1[[#This Row],[BB]]+Table1[[#This Row],[SF]] -> 3 | AG8: =Table1[[#This Row],[H]]+Table1[[#This Row],[BB]] -> 1 | AH8: =Table1[[#This Row],[H]]-Table1[[#This Row],[2B]]-Table1[[#This Row],[3B]]-Table1[[#This Row],[HR]] -> 1 | AI8: =IF(Table1[[#This Row],[Team_Game_Number]] >_xlfn.MAXIFS(Table1[Team_Game_Number],Table1[Team],Table1[[#This Row],[Team]]) - 5,1,0) -> 0 | AJ8: {=MATCH(Table1[[#This Row],[Game_ID]],_xlfn.UNIQUE(_xlfn._xlws.FILTER(Table1[Game_ID],Table1[Team]=Table1[[#This Row],[Team]])),0)} -> 1 | AK8: =IF(Table1[[#This Row],[Last5_Flag]]=1,1,0) -> 0 | AL8: =COUNTIFS( Table1[Player Name], Table1[[#This Row],[Player Name]], Table1[Position], Table1[[#This Row],[Position]] ) -> 6 | AM8: {=IFERROR( _xlfn.LET( _xlpm.player, Table1[[#This Row],[Player Name]], _xlpm.uPos, _xlfn.UNIQUE(_xlfn._xlws.FILTER(Table1[Position], Table1[Player Name]=_xlpm.player)), _xlpm.counts, _xlfn.MAP(_xlpm.uPos, _xlfn.LAMBDA(_xlpm.p, COUNTIFS(Table1[Player Name], _xlpm.player, Table1[Position], _xlpm.p))), INDEX(_xlpm.uPos, MATCH(MAX(_xlpm.counts), _xlpm.counts, 0)) ), "N/A")} -> LF
A9: =TEXT(Table1[[#This Row],[Date]],"yyyymmdd") & "_" & (LEFT(D9,3) & "_" & LEFT(E9,3) & "_" & (Table1[[#This Row],[Game_no.]])) -> 20260130_UNC_D&E_1 | B9: 46052 | C9: 1 | D9: UNC Pembroke | E9: D&E | F9: D&E | G9: UNC Pembroke | H9: M.Smith | I9: =TRIM(SUBSTITUTE(Table1[[#This Row],[Player]], " ", "")) -> M.Smith | J9: 1 | K9: 0 | L9: 1 | M9: 1 | N9: 2 | O9: 0 | P9: 0 | Q9: 0 | R9: 0 | S9: 0 | T9: 0 | U9: 0 | V9: =L9*1+P9*2+Q9*3+R9*4 -> 1 | W9: RF | X9: 8 | Y9: 0 | AF9: =Table1[[#This Row],[AB]]+Table1[[#This Row],[BB]]+Table1[[#This Row],[SF]] -> 3 | AG9: =Table1[[#This Row],[H]]+Table1[[#This Row],[BB]] -> 3 | AH9: =Table1[[#This Row],[H]]-Table1[[#This Row],[2B]]-Table1[[#This Row],[3B]]-Table1[[#This Row],[HR]] -> 1 | AI9: =IF(Table1[[#This Row],[Team_Game_Number]] >_xlfn.MAXIFS(Table1[Team_Game_Number],Table1[Team],Table1[[#This Row],[Team]]) - 5,1,0) -> 0 | AJ9: {=MATCH(Table1[[#This Row],[Game_ID]],_xlfn.UNIQUE(_xlfn._xlws.FILTER(Table1[Game_ID],Table1[Team]=Table1[[#This Row],[Team]])),0)} -> 1 | AK9: =IF(Table1[[#This Row],[Last5_Flag]]=1,1,0) -> 0 | AL9: =COUNTIFS( Table1[Player Name], Table1[[#This Row],[Player Name]], Table1[Position], Table1[[#This Row],[Position]] ) -> 21 | AM9: {=IFERROR( _xlfn.LET( _xlpm.player, Table1[[#This Row],[Player Name]], _xlpm.uPos, _xlfn.UNIQUE(_xlfn._xlws.FILTER(Table1[Position], Table1[Player Name]=_xlpm.player)), _xlpm.counts, _xlfn.MAP(_xlpm.uPos, _xlfn.LAMBDA(_xlpm.p, COUNTIFS(Table1[Player Name], _xlpm.player, Table1[Position], _xlpm.p))), INDEX(_xlpm.uPos, MATCH(MAX(_xlpm.counts), _xlpm.counts, 0)) ), "N/A")} -> RF
A10: =TEXT(Table1[[#This Row],[Date]],"yyyymmdd") & "_" & (LEFT(D10,3) & "_" & LEFT(E10,3) & "_" & (Table1[[#This Row],[Game_no.]])) -> 20260130_UNC_D&E_1 | B10: 46052 | C10: 1 | D10: UNC Pembroke | E10: D&E | F10: D&E | G10: UNC Pembroke | H10: C.Warfield | I10: =TRIM(SUBSTITUTE(Table1[[#This Row],[Player]], " ", "")) -> C.Warfield | J10: 1 | K10: 0 | L10: 0 | M10: 1 | N10: 1 | O10: 1 | P10: 0 | Q10: 0 | R10: 0 | S10: 0 | T10: 0 | U10: 0 | V10: =L10*1+P10*2+Q10*3+R10*4 -> 0 | W10: CF | X10: 9 | Y10: 0 | AF10: =Table1[[#This Row],[AB]]+Table1[[#This Row],[BB]]+Table1[[#This Row],[SF]] -> 2 | AG10: =Table1[[#This Row],[H]]+Table1[[#This Row],[BB]] -> 1 | AH10: =Table1[[#This Row],[H]]-Table1[[#This Row],[2B]]-Table1[[#This Row],[3B]]-Table1[[#This Row],[HR]] -> 0 | AI10: =IF(Table1[[#This Row],[Team_Game_Number]] >_xlfn.MAXIFS(Table1[Team_Game_Number],Table1[Team],Table1[[#This Row],[Team]]) - 5,1,0) -> 0 | AJ10: {=MATCH(Table1[[#This Row],[Game_ID]],_xlfn.UNIQUE(_xlfn._xlws.FILTER(Table1[Game_ID],Table1[Team]=Table1[[#This Row],[Team]])),0)} -> 1 | AK10: =IF(Table1[[#This Row],[Last5_Flag]]=1,1,0) -> 0 | AL10: =COUNTIFS( Table1[Player Name], Table1[[#This Row],[Player Name]], Table1[Position], Table1[[#This Row],[Position]] ) -> 6 | AM10: {=IFERROR( _xlfn.LET( _xlpm.player, Table1[[#This Row],[Player Name]], _xlpm.uPos, _xlfn.UNIQUE(_xlfn._xlws.FILTER(Table1[Position], Table1[Player Name]=_xlpm.player)), _xlpm.counts, _xlfn.MAP(_xlpm.uPos, _xlfn.LAMBDA(_xlpm.p, COUNTIFS(Table1[Player Name], _xlpm.player, Table1[Position], _xlpm.p))), INDEX(_xlpm.uPos, MATCH(MAX(_xlpm.counts), _xlpm.counts, 0)) ), "N/A")} -> CF
A11: =TEXT(Table1[[#This Row],[Date]],"yyyymmdd") & "_" & (LEFT(D11,3) & "_" & LEFT(E11,3) & "_" & (Table1[[#This Row],[Game_no.]])) -> 20260130_UNC_D&E_1 | B11: 46052 | C11: 1 | D11: UNC Pembroke | E11: D&E | F11: D&E | G11: UNC Pembroke | H11: S.Kneeland | I11: =TRIM(SUBSTITUTE(Table1[[#This Row],[Player]], " ", "")) -> S.Kneeland | J11: 0 | K11: 0 | L11: 0 | M11: 0 | N11: 0 | O11: 0 | P11: 0 | Q11: 0 | R11: 0 | S11: 0 | T11: 0 | U11: 0 | V11: =L11*1+P11*2+Q11*3+R11*4 -> 0 | W11: P | Y11: 1 | Z11: 3.667 | AA11: 9 | AB11: 8 | AC11: 7 | AD11: 0 | AE11: 3 | AF11: =Table1[[#This Row],[AB]]+Table1[[#This Row],[BB]]+Table1[[#This Row],[SF]] -> 0 | AG11: =Table1[[#This Row],[H]]+Table1[[#This Row],[BB]] -> 0 | AH11: =Table1[[#This Row],[H]]-Table1[[#This Row],[2B]]-Table1[[#This Row],[3B]]-Table1[[#This Row],[HR]] -> 0 | AI11: =IF(Table1[[#This Row],[Team_Game_Number]] >_xlfn.MAXIFS(Table1[Team_Game_Number],Table1[Team],Table1[[#This Row],[Team]]) - 5,1,0) -> 0 | AJ11: {=MATCH(Table1[[#This Row],[Game_ID]],_xlfn.UNIQUE(_xlfn._xlws.FILTER(Table1[Game_ID],Table1[Team]=Table1[[#This Row],[Team]])),0)} -> 1 | AK11: =IF(Table1[[#This Row],[Last5_Flag]]=1,1,0) -> 0 | AL11: =COUNTIFS( Table1[Player Name], Table1[[#This Row],[Player Name]], Table1[Position], Table1[[#This Row],[Position]] ) -> 17 | AM11: {=IFERROR( _xlfn.LET( _xlpm.player, Table1[[#This Row],[Player Name]], _xlpm.uPos, _xlfn.UNIQUE(_xlfn._xlws.FILTER(Table1[Position], Table1[Player Name]=_xlpm.player)), _xlpm.counts, _xlfn.MAP(_xlpm.uPos, _xlfn.LAMBDA(_xlpm.p, COUNTIFS(Table1[Player Name], _xlpm.player, Table1[Position], _xlpm.p))), INDEX(_xlpm.uPos, MATCH(MAX(_xlpm.counts), _xlpm.counts, 0)) ), "N/A")} -> P
A12: =TEXT(Table1[[#This Row],[Date]],"yyyymmdd") & "_" & (LEFT(D12,3) & "_" & LEFT(E12,3) & "_" & (Table1[[#This Row],[Game_no.]])) -> 20260130_UNC_D&E_1 | B12: 46052 | C12: 1 | D12: UNC Pembroke | E12: D&E | F12: D&E | G12: UNC Pembroke | H12: A.Munoz | I12: =TRIM(SUBSTITUTE(Table1[[#This Row],[Player]], " ", "")) -> A.Munoz | J12: 0 | K12: 0 | L12: 0 | M12: 0 | N12: 0 | O12: 0 | P12: 0 | Q12: 0 | R12: 0 | S12: 0 | T12: 0 | U12: 0 | V12: =L12*1+P12*2+Q12*3+R12*4 -> 0 | W12: P | Y12: 0 | Z12: 1 | AA12: 6 | AB12: 4 | AC12: 3 | AD12: 1 | AE12: 1 | AF12: =Table1[[#This Row],[AB]]+Table1[[#This Row],[BB]]+Table1[[#This Row],[SF]] -> 0 | AG12: =Table1[[#This Row],[H]]+Table1[[#This Row],[BB]] -> 0 | AH12: =Table1[[#This Row],[H]]-Table1[[#This Row],[2B]]-Table1[[#This Row],[3B]]-Table1[[#This Row],[HR]] -> 0 | AI12: =IF(Table1[[#This Row],[Team_Game_Number]] >_xlfn.MAXIFS(Table1[Team_Game_Number],Table1[Team],Table1[[#This Row],[Team]]) - 5,1,0) -> 0 | AJ12: {=MATCH(Table1[[#This Row],[Game_ID]],_xlfn.UNIQUE(_xlfn._xlws.FILTER(Table1[Game_ID],Table1[Team]=Table1[[#This Row],[Team]])),0)} -> 1 | AK12: =IF(Table1[[#This Row],[Last5_Flag]]=1,1,0) -> 0 | AL12: =COUNTIFS( Table1[Player Name], Table1[[#This Row],[Player Name]], Table1[Position], Table1[[#This Row],[Position]] ) -> 10 | AM12: {=IFERROR( _xlfn.LET( _xlpm.player, Table1[[#This Row],[Player Name]], _xlpm.uPos, _xlfn.UNIQUE(_xlfn._xlws.FILTER(Table1[Position], Table1[Player Name]=_xlpm.player)), _xlpm.counts, _xlfn.MAP(_xlpm.uPos, _xlfn.LAMBDA(_xlpm.p, COUNTIFS(Table1[Player Name], _xlpm.player, Table1[Position], _xlpm.p))), INDEX(_xlpm.uPos, MATCH(MAX(_xlpm.counts), _xlpm.counts, 0)) ), "N/A")} -> P
A13: =TEXT(Table1[[#This Row],[Date]],"yyyymmdd") & "_" & (LEFT(D13,3) & "_" & LEFT(E13,3) & "_" & (Table1[[#This Row],[Game_no.]])) -> 20260130_UNC_D&E_2 | B13: 46052 | C13: 2 | D13: UNC Pembroke | E13: D&E | F13: D&E | G13: UNC Pembroke | H13: A.Haynes | I13: =TRIM(SUBSTITUTE(Table1[[#This Row],[Player]], " ", "")) -> A.Haynes | J13: 2 | K13: 1 | L13: 1 | M13: 0 | N13: 1 | O13: 0 | P13: 0 | Q13: 0 | R13: 0 | S13: 0 | T13: 0 | U13: 0 | V13: =L13*1+P13*2+Q13*3+R13*4 -> 1 | W13: CF | X13: 1 | Y13: 1 | AF13: =Table1[[#This Row],[AB]]+Table1[[#This Row],[BB]]+Table1[[#This Row],[SF]] -> 3 | AG13: =Table1[[#This Row],[H]]+Table1[[#This Row],[BB]] -> 2 | AH13: =Table1[[#This Row],[H]]-Table1[[#This Row],[2B]]-Table1[[#This Row],[3B]]-Table1[[#This Row],[HR]] -> 1 | AI13: =IF(Table1[[#This Row],[Team_Game_Number]] >_xlfn.MAXIFS(Table1[Team_Game_Number],Table1[Team],Table1[[#This Row],[Team]]) - 5,1,0) -> 0 | AJ13: {=MATCH(Table1[[#This Row],[Game_ID]],_xlfn.UNIQUE(_xlfn._xlws.FILTER(Table1[Game_ID],Table1[Team]=Table1[[#This Row],[Team]])),0)} -> 2 | AK13: =IF(Table1[[#This Row],[Last5_Flag]]=1,1,0) -> 0 | AL13: =COUNTIFS( Table1[Player Name], Table1[[#This Row],[Player Name]], Table1[Position], Table1[[#This Row],[Position]] ) -> 3 | AM13: {=IFERROR( _xlfn.LET( _xlpm.player, Table1[[#This Row],[Player Name]], _xlpm.uPos, _xlfn.UNIQUE(_xlfn._xlws.FILTER(Table1[Position], Table1[Player Name]=_xlpm.player)), _xlpm.counts, _xlfn.MAP(_xlpm.uPos, _xlfn.LAMBDA(_xlpm.p, COUNTIFS(Table1[Player Name], _xlpm.player, Table1[Position], _xlpm.p))), INDEX(_xlpm.uPos, MATCH(MAX(_xlpm.counts), _xlpm.counts, 0)) ), "N/A")} -> LF
A14: =TEXT(Table1[[#This Row],[Date]],"yyyymmdd") & "_" & (LEFT(D14,3) & "_" & LEFT(E14,3) & "_" & (Table1[[#This Row],[Game_no.]])) -> 20260130_UNC_D&E_2 | B14: 46052 | C14: 2 | D14: UNC Pembroke | E14: D&E | F14: D&E | G14: UNC Pembroke | H14: C.Dobbs | I14: =TRIM(SUBSTITUTE(Table1[[#This Row],[Player]], " ", "")) -> C.Dobbs | J14: 2 | K14: 1 | L14: 0 | M14: 0 | N14: 1 | O14: 1 | P14: 0 | Q14: 0 | R14: 0 | S14: 0 | T14: 0 | U14: 0 | V14: =L14*1+P14*2+Q14*3+R14*4 -> 0 | W14: 2B | X14: 2 | Y14: 0 | AF14: =Table1[[#This Row],[AB]]+Table1[[#This Row],[BB]]+Table1[[#This Row],[SF]] -> 3 | AG14: =Table1[[#This Row],[H]]+Table1[[#This Row],[BB]] -> 1 | AH14: =Table1[[#This Row],[H]]-Table1[[#This Row],[2B]]-Table1[[#This Row],[3B]]-Table1[[#This Row],[HR]] -> 0 | AI14: =IF(Table1[[#This Row],[Team_Game_Number]] >_xlfn.MAXIFS(Table1[Team_Game_Number],Table1[Team],Table1[[#This Row],[Team]]) - 5,1,0) -> 0 | AJ14: {=MATCH(Table1[[#This Row],[Game_ID]],_xlfn.UNIQUE(_xlfn._xlws.FILTER(Table1[Game_ID],Table1[Team]=Table1[[#This Row],[Team]])),0)} -> 2 | AK14: =IF(Table1[[#This Row],[Last5_Flag]]=1,1,0) -> 0 | AL14: =COUNTIFS( Table1[Player Name], Table1[[#This Row],[Player Name]], Table1[Position], Table1[[#This Row],[Position]] ) -> 3 | AM14: {=IFERROR( _xlfn.LET( _xlpm.player, Table1[[#This Row],[Player Name]], _xlpm.uPos, _xlfn.UNIQUE(_xlfn._xlws.FILTER(Table1[Position], Table1[Player Name]=_xlpm.player)), _xlpm.counts, _xlfn.MAP(_xlpm.uPos, _xlfn.LAMBDA(_xlpm.p, COUNTIFS(Table1[Player Name], _xlpm.player, Table1[Position], _xlpm.p))), INDEX(_xlpm.uPos, MATCH(MAX(_xlpm.counts), _xlpm.counts, 0)) ), "N/A")} -> SS
A15: =TEXT(Table1[[#This Row],[Date]],"yyyymmdd") & "_" & (LEFT(D15,3) & "_" & LEFT(E15,3) & "_" & (Table1[[#This Row],[Game_no.]])) -> 20260130_UNC_D&E_2 | B15: 46052 | C15: 2 | D15: UNC Pembroke | E15: D&E | F15: D&E | G15: UNC Pembroke | H15: A.Zapach | I15: =TRIM(SUBSTITUTE(Table1[[#This Row],[Player]], " ", "")) -> A.Zapach | J15: 1 | K15: 0 | L15: 1 | M15: 2 | N15: 2 | O15: 0 | P15: 1 | Q15: 0 | R15: 0 | S15: 0 | T15: 0 | U15: 0 | V15: =L15*1+P15*2+Q15*3+R15*4 -> 3 | W15: 1B | X15: 3 | Y15: 0 | AF15: =Table1[[#This Row],[AB]]+Table1[[#This Row],[BB]]+Table1[[#This Row],[SF]] -> 3 | AG15: =Table1[[#This Row],[H]]+Table1[[#This Row],[BB]] -> 3 | AH15: =Table1[[#This Row],[H]]-Table1[[#This Row],[2B]]-Table1[[#This Row],[3B]]-Table1[[#This Row],[HR]] -> 0 | AI15: =IF(Table1[[#This Row],[Team_Game_Number]] >_xlfn.MAXIFS(Table1[Team_Game_Number],Table1[Team],Table1[[#This Row],[Team]]) - 5,1,0) -> 0 | AJ15: {=MATCH(Table1[[#This Row],[Game_ID]],_xlfn.UNIQUE(_xlfn._xlws.FILTER(Table1[Game_ID],Table1[Team]=Table1[[#This Row],[Team]])),0)} -> 2 | AK15: =IF(Table1[[#This Row],[Last5_Flag]]=1,1,0) -> 0 | AL15: =COUNTIFS( Table1[Player Name], Table1[[#This Row],[Player Name]], Table1[Position], Table1[[#This Row],[Position]] ) -> 27 | AM15: {=IFERROR( _xlfn.LET( _xlpm.player, Table1[[#This Row],[Player Name]], _xlpm.uPos, _xlfn.UNIQUE(_xlfn._xlws.FILTER(Table1[Position], Table1[Player Name]=_xlpm.player)), _xlpm.counts, _xlfn.MAP(_xlpm.uPos, _xlfn.LAMBDA(_xlpm.p, COUNTIFS(Table1[Player Name], _xlpm.player, Table1[Position], _xlpm.p))), INDEX(_xlpm.uPos, MATCH(MAX(_xlpm.counts), _xlpm.counts, 0)) ), "N/A")} -> 1B
